Workbook

Sheet Mode d'emploi
A1: MODE D'EMPLOI — Tableau des dépenses mensuelles
A3: 1. Onglet « Charges fixes » : saisissez UNE SEULE FOIS vos abonnements et factures récurrentes
A4: (loyer, garage, téléphone, wifi, mutuelle, assurance auto, Shopify, Google/Meta/TikTok Ads…).
A5: → Montant, fréquence (Mensuel / Trimestriel / Semestriel / Annuel), jour du prélèvement, mode de paiement.
A6: → Pour une charge non mensuelle, indiquez le « Mois du 1er paiement » (ex. assurance auto annuelle → Janvier).
A7: Exemple : Logement | Loyer | 650 € | Mensuel | (vide) | 5 | Virement → apparaît le 05 de chaque mois.
A9: 2. Onglets mensuels (Octobre 2026 → Septembre 2027) : les charges fixes s'y affichent automatiquement,
A10: avec la date exacte de paiement / prélèvement.
A11: → En bas, section « Dépenses ponctuelles » : ajoutez les frais du mois (facture d'hôpital, réparation…).
A12: → Colonne « Payé ? » : mettez Oui quand l'argent est sorti. Rouge = en retard, orange = dans les 7 jours.
A13: → Un montant différent ce mois-ci (ex. facture d'électricité) ? Tapez-le directement dans la cellule.
A15: 3. Onglet « Récapitulatif » : totaux par catégorie et par mois, total annuel, moyenne et graphique.
... A22: Texte noir = formules automatiques (ne pas effacer). Texte vert = repris d'un autre onglet.

Sheet Récapitulatif
A1: Récapitulatif des dépenses — Octobre 2026 à Septembre 2027
A2: Tout se calcule automatiquement à partir des onglets mensuels. Ne rien saisir ici.
A4: Catégorie | B4: Octobre 26 | C4: Novembre 26 | D4: Décembre 26 | E4: Janvier 27 | F4: Février 27 | G4: Mars 27 | H4: Avril 27 | I4: Mai 27 | J4: Juin 27 | K4: Juillet 27 | L4: Août 27 | M4: Septembre 27 | N4: Total année | O4: Moyenne / mois
A5: =IF(Paramètres!A4="","",Paramètres!A4) | B5: =IF($A5="","",SUMIFS('Octobre 2026'!$C$8:$C$88,'Octobre 2026'!$A$8:$A$88,$A5)) | C5: =IF($A5="","",SUMIFS('Novembre 2026'!$C$8:$C$88,'Novembre 2026'!$A$8:$A$88,$A5)) | D5: =IF($A5="","",SUMIFS('Décembre 2026'!$C$8:$C$88,'Décembre 2026'!$A$8:$A$88,$A5)) | E5: =IF($A5="","",SUMIFS('Janvier 2027'!$C$8:$C$88,'Janvier 2027'!$A$8:$A$88,$A5)) | F5: =IF($A5="","",SUMIFS('Février 2027'!$C$8:$C$88,'Février 2027'!$A$8:$A$88,$A5)) | G5: =IF($A5="","",SUMIFS('Mars 2027'!$C$8:$C$88,'Mars 2027'!$A$8:$A$88,$A5)) | H5: =IF($A5="","",SUMIFS('Avril 2027'!$C$8:$C$88,'Avril 2027'!$A$8:$A$88,$A5)) | I5: =IF($A5="","",SUMIFS('Mai 2027'!$C$8:$C$88,'Mai 2027'!$A$8:$A$88,$A5)) | J5: =IF($A5="","",SUMIFS('Juin 2027'!$C$8:$C$88,'Juin 2027'!$A$8:$A$88,$A5)) | K5: =IF($A5="","",SUMIFS('Juillet 2027'!$C$8:$C$88,'Juillet 2027'!$A$8:$A$88,$A5)) | L5: =IF($A5="","",SUMIFS('Août 2027'!$C$8:$C$88,'Août 2027'!$A$8:$A$88,$A5)) | M5: =IF($A5="","",SUMIFS('Septembre 2027'!$C$8:$C$88,'Septembre 2027'!$A$8:$A$88,$A5)) | N5: =IF($A5="","",SUM(B5:M5)) | O5: =IF($A5="","",N5/12)
A6: =IF(Paramètres!A5="","",Paramètres!A5) | B6: =IF($A6="","",SUMIFS('Octobre 2026'!$C$8:$C$88,'Octobre 2026'!$A$8:$A$88,$A6)) | C6: =IF($A6="","",SUMIFS('Novembre 2026'!$C$8:$C$88,'Novembre 2026'!$A$8:$A$88,$A6)) | D6: =IF($A6="","",SUMIFS('Décembre 2026'!$C$8:$C$88,'Décembre 2026'!$A$8:$A$88,$A6)) | E6: =IF($A6="","",SUMIFS('Janvier 2027'!$C$8:$C$88,'Janvier 2027'!$A$8:$A$88,$A6)) | F6: =IF($A6="","",SUMIFS('Février 2027'!$C$8:$C$88,'Février 2027'!$A$8:$A$88,$A6)) | G6: =IF($A6="","",SUMIFS('Mars 2027'!$C$8:$C$88,'Mars 2027'!$A$8:$A$88,$A6)) | H6: =IF($A6="","",SUMIFS('Avril 2027'!$C$8:$C$88,'Avril 2027'!$A$8:$A$88,$A6)) | I6: =IF($A6="","",SUMIFS('Mai 2027'!$C$8:$C$88,'Mai 2027'!$A$8:$A$88,$A6)) | J6: =IF($A6="","",SUMIFS('Juin 2027'!$C$8:$C$88,'Juin 2027'!$A$8:$A$88,$A6)) | K6: =IF($A6="","",SUMIFS('Juillet 2027'!$C$8:$C$88,'Juillet 2027'!$A$8:$A$88,$A6)) | L6: =IF($A6="","",SUMIFS('Août 2027'!$C$8:$C$88,'Août 2027'!$A$8:$A$88,$A6)) | M6: =IF($A6="","",SUMIFS('Septembre 2027'!$C$8:$C$88,'Septembre 2027'!$A$8:$A$88,$A6)) | N6: =IF($A6="","",SUM(B6:M6)) | O6: =IF($A6="","",N6/12)
A7: =IF(Paramètres!A6="","",Paramètres!A6) | B7: =IF($A7="","",SUMIFS('Octobre 2026'!$C$8:$C$88,'Octobre 2026'!$A$8:$A$88,$A7)) | C7: =IF($A7="","",SUMIFS('Novembre 2026'!$C$8:$C$88,'Novembre 2026'!$A$8:$A$88,$A7)) | D7: =IF($A7="","",SUMIFS('Décembre 2026'!$C$8:$C$88,'Décembre 2026'!$A$8:$A$88,$A7)) | E7: =IF($A7="","",SUMIFS('Janvier 2027'!$C$8:$C$88,'Janvier 2027'!$A$8:$A$88,$A7)) | F7: =IF($A7="","",SUMIFS('Février 2027'!$C$8:$C$88,'Février 2027'!$A$8:$A$88,$A7)) | G7: =IF($A7="","",SUMIFS('Mars 2027'!$C$8:$C$88,'Mars 2027'!$A$8:$A$88,$A7)) | H7: =IF($A7="","",SUMIFS('Avril 2027'!$C$8:$C$88,'Avril 2027'!$A$8:$A$88,$A7)) | I7: =IF($A7="","",SUMIFS('Mai 2027'!$C$8:$C$88,'Mai 2027'!$A$8:$A$88,$A7)) | J7: =IF($A7="","",SUMIFS('Juin 2027'!$C$8:$C$88,'Juin 2027'!$A$8:$A$88,$A7)) | K7: =IF($A7="","",SUMIFS('Juillet 2027'!$C$8:$C$88,'Juillet 2027'!$A$8:$A$88,$A7)) | L7: =IF($A7="","",SUMIFS('Août 2027'!$C$8:$C$88,'Août 2027'!$A$8:$A$88,$A7)) | M7: =IF($A7="","",SUMIFS('Septembre 2027'!$C$8:$C$88,'Septembre 2027'!$A$8:$A$88,$A7)) | N7: =IF($A7="","",SUM(B7:M7)) | O7: =IF($A7="","",N7/12)
A8: =IF(Paramètres!A7="","",Paramètres!A7) | B8: =IF($A8="","",SUMIFS('Octobre 2026'!$C$8:$C$88,'Octobre 2026'!$A$8:$A$88,$A8)) | C8: =IF($A8="","",SUMIFS('Novembre 2026'!$C$8:$C$88,'Novembre 2026'!$A$8:$A$88,$A8)) | D8: =IF($A8="","",SUMIFS('Décembre 2026'!$C$8:$C$88,'Décembre 2026'!$A$8:$A$88,$A8)) | E8: =IF($A8="","",SUMIFS('Janvier 2027'!$C$8:$C$88,'Janvier 2027'!$A$8:$A$88,$A8)) | F8: =IF($A8="","",SUMIFS('Février 2027'!$C$8:$C$88,'Février 2027'!$A$8:$A$88,$A8)) | G8: =IF($A8="","",SUMIFS('Mars 2027'!$C$8:$C$88,'Mars 2027'!$A$8:$A$88,$A8)) | H8: =IF($A8="","",SUMIFS('Avril 2027'!$C$8:$C$88,'Avril 2027'!$A$8:$A$88,$A8)) | I8: =IF($A8="","",SUMIFS('Mai 2027'!$C$8:$C$88,'Mai 2027'!$A$8:$A$88,$A8)) | J8: =IF($A8="","",SUMIFS('Juin 2027'!$C$8:$C$88,'Juin 2027'!$A$8:$A$88,$A8)) | K8: =IF($A8="","",SUMIFS('Juillet 2027'!$C$8:$C$88,'Juillet 2027'!$A$8:$A$88,$A8)) | L8: =IF($A8="","",SUMIFS('Août 2027'!$C$8:$C$88,'Août 2027'!$A$8:$A$88,$A8)) | M8: =IF($A8="","",SUMIFS('Septembre 2027'!$C$8:$C$88,'Septembre 2027'!$A$8:$A$88,$A8)) | N8: =IF($A8="","",SUM(B8:M8)) | O8: =IF($A8="","",N8/12)
A9: =IF(Paramètres!A8="","",Paramètres!A8) | B9: =IF($A9="","",SUMIFS('Octobre 2026'!$C$8:$C$88,'Octobre 2026'!$A$8:$A$88,$A9)) | C9: =IF($A9="","",SUMIFS('Novembre 2026'!$C$8:$C$88,'Novembre 2026'!$A$8:$A$88,$A9)) | D9: =IF($A9="","",SUMIFS('Décembre 2026'!$C$8:$C$88,'Décembre 2026'!$A$8:$A$88,$A9)) | E9: =IF($A9="","",SUMIFS('Janvier 2027'!$C$8:$C$88,'Janvier 2027'!$A$8:$A$88,$A9)) | F9: =IF($A9="","",SUMIFS('Février 2027'!$C$8:$C$88,'Février 2027'!$A$8:$A$88,$A9)) | G9: =IF($A9="","",SUMIFS('Mars 2027'!$C$8:$C$88,'Mars 2027'!$A$8:$A$88,$A9)) | H9: =IF($A9="","",SUMIFS('Avril 2027'!$C$8:$C$88,'Avril 2027'!$A$8:$A$88,$A9)) | I9: =IF($A9="","",SUMIFS('Mai 2027'!$C$8:$C$88,'Mai 2027'!$A$8:$A$88,$A9)) | J9: =IF($A9="","",SUMIFS('Juin 2027'!$C$8:$C$88,'Juin 2027'!$A$8:$A$88,$A9)) | K9: =IF($A9="","",SUMIFS('Juillet 2027'!$C$8:$C$88,'Juillet 2027'!$A$8:$A$88,$A9)) | L9: =IF($A9="","",SUMIFS('Août 2027'!$C$8:$C$88,'Août 2027'!$A$8:$A$88,$A9)) | M9: =IF($A9="","",SUMIFS('Septembre 2027'!$C$8:$C$88,'Septembre 2027'!$A$8:$A$88,$A9)) | N9: =IF($A9="","",SUM(B9:M9)) | O9: =IF($A9="","",N9/12)
A10: =IF(Paramètres!A9="","",Paramètres!A9) | B10: =IF($A10="","",SUMIFS('Octobre 2026'!$C$8:$C$88,'Octobre 2026'!$A$8:$A$88,$A10)) | C10: =IF($A10="","",SUMIFS('Novembre 2026'!$C$8:$C$88,'Novembre 2026'!$A$8:$A$88,$A10)) | D10: =IF($A10="","",SUMIFS('Décembre 2026'!$C$8:$C$88,'Décembre 2026'!$A$8:$A$88,$A10)) | E10: =IF($A10="","",SUMIFS('Janvier 2027'!$C$8:$C$88,'Janvier 2027'!$A$8:$A$88,$A10)) | F10: =IF($A10="","",SUMIFS('Février 2027'!$C$8:$C$88,'Février 2027'!$A$8:$A$88,$A10)) | G10: =IF($A10="","",SUMIFS('Mars 2027'!$C$8:$C$88,'Mars 2027'!$A$8:$A$88,$A10)) | H10: =IF($A10="","",SUMIFS('Avril 2027'!$C$8:$C$88,'Avril 2027'!$A$8:$A$88,$A10)) | I10: =IF($A10="","",SUMIFS('Mai 2027'!$C$8:$C$88,'Mai 2027'!$A$8:$A$88,$A10)) | J10: =IF($A10="","",SUMIFS('Juin 2027'!$C$8:$C$88,'Juin 2027'!$A$8:$A$88,$A10)) | K10: =IF($A10="","",SUMIFS('Juillet 2027'!$C$8:$C$88,'Juillet 2027'!$A$8:$A$88,$A10)) | L10: =IF($A10="","",SUMIFS('Août 2027'!$C$8:$C$88,'Août 2027'!$A$8:$A$88,$A10)) | M10: =IF($A10="","",SUMIFS('Septembre 2027'!$C$8:$C$88,'Septembre 2027'!$A$8:$A$88,$A10)) | N10: =IF($A10="","",SUM(B10:M10)) | O10: =IF($A10="","",N10/12)
A11: =IF(Paramètres!A10="","",Paramètres!A10) | B11: =IF($A11="","",SUMIFS('Octobre 2026'!$C$8:$C$88,'Octobre 2026'!$A$8:$A$88,$A11)) | C11: =IF($A11="","",SUMIFS('Novembre 2026'!$C$8:$C$88,'Novembre 2026'!$A$8:$A$88,$A11)) | D11: =IF($A11="","",SUMIFS('Décembre 2026'!$C$8:$C$88,'Décembre 2026'!$A$8:$A$88,$A11)) | E11: =IF($A11="","",SUMIFS('Janvier 2027'!$C$8:$C$88,'Janvier 2027'!$A$8:$A$88,$A11)) | F11: =IF($A11="","",SUMIFS('Février 2027'!$C$8:$C$88,'Février 2027'!$A$8:$A$88,$A11)) | G11: =IF($A11="","",SUMIFS('Mars 2027'!$C$8:$C$88,'Mars 2027'!$A$8:$A$88,$A11)) | H11: =IF($A11="","",SUMIFS('Avril 2027'!$C$8:$C$88,'Avril 2027'!$A$8:$A$88,$A11)) | I11: =IF($A11="","",SUMIFS('Mai 2027'!$C$8:$C$88,'Mai 2027'!$A$8:$A$88,$A11)) | J11: =IF($A11="","",SUMIFS('Juin 2027'!$C$8:$C$88,'Juin 2027'!$A$8:$A$88,$A11)) | K11: =IF($A11="","",SUMIFS('Juillet 2027'!$C$8:$C$88,'Juillet 2027'!$A$8:$A$88,$A11)) | L11: =IF($A11="","",SUMIFS('Août 2027'!$C$8:$C$88,'Août 2027'!$A$8:$A$88,$A11)) | M11: =IF($A11="","",SUMIFS('Septembre 2027'!$C$8:$C$88,'Septembre 2027'!$A$8:$A$88,$A11)) | N11: =IF($A11="","",SUM(B11:M11)) | O11: =IF($A11="","",N11/12)
A12: =IF(Paramètres!A11="","",Paramètres!A11) | B12: =IF($A12="","",SUMIFS('Octobre 2026'!$C$8:$C$88,'Octobre 2026'!$A$8:$A$88,$A12)) | C12: =IF($A12="","",SUMIFS('Novembre 2026'!$C$8:$C$88,'Novembre 2026'!$A$8:$A$88,$A12)) | D12: =IF($A12="","",SUMIFS('Décembre 2026'!$C$8:$C$88,'Décembre 2026'!$A$8:$A$88,$A12)) | E12: =IF($A12="","",SUMIFS('Janvier 2027'!$C$8:$C$88,'Janvier 2027'!$A$8:$A$88,$A12)) | F12: =IF($A12="","",SUMIFS('Février 2027'!$C$8:$C$88,'Février 2027'!$A$8:$A$88,$A12)) | G12: =IF($A12="","",SUMIFS('Mars 2027'!$C$8:$C$88,'Mars 2027'!$A$8:$A$88,$A12)) | H12: =IF($A12="","",SUMIFS('Avril 2027'!$C$8:$C$88,'Avril 2027'!$A$8:$A$88,$A12)) | I12: =IF($A12="","",SUMIFS('Mai 2027'!$C$8:$C$88,'Mai 2027'!$A$8:$A$88,$A12)) | J12: =IF($A12="","",SUMIFS('Juin 2027'!$C$8:$C$88,'Juin 2027'!$A$8:$A$88,$A12)) | K12: =IF($A12="","",SUMIFS('Juillet 2027'!$C$8:$C$88,'Juillet 2027'!$A$8:$A$88,$A12)) | L12: =IF($A12="","",SUMIFS('Août 2027'!$C$8:$C$88,'Août 2027'!$A$8:$A$88,$A12)) | M12: =IF($A12="","",SUMIFS('Septembre 2027'!$C$8:$C$88,'Septembre 2027'!$A$8:$A$88,$A12)) | N12: =IF($A12="","",SUM(B12:M12)) | O12: =IF($A12="","",N12/12)
A13: =IF(Paramètres!A12="","",Paramètres!A12) | B13: =IF($A13="","",SUMIFS('Octobre 2026'!$C$8:$C$88,'Octobre 2026'!$A$8:$A$88,$A13)) | C13: =IF($A13="","",SUMIFS('Novembre 2026'!$C$8:$C$88,'Novembre 2026'!$A$8:$A$88,$A13)) | D13: =IF($A13="","",SUMIFS('Décembre 2026'!$C$8:$C$88,'Décembre 2026'!$A$8:$A$88,$A13)) | E13: =IF($A13="","",SUMIFS('Janvier 2027'!$C$8:$C$88,'Janvier 2027'!$A$8:$A$88,$A13)) | F13: =IF($A13="","",SUMIFS('Février 2027'!$C$8:$C$88,'Février 2027'!$A$8:$A$88,$A13)) | G13: =IF($A13="","",SUMIFS('Mars 2027'!$C$8:$C$88,'Mars 2027'!$A$8:$A$88,$A13)) | H13: =IF($A13="","",SUMIFS('Avril 2027'!$C$8:$C$88,'Avril 2027'!$A$8:$A$88,$A13)) | I13: =IF($A13="","",SUMIFS('Mai 2027'!$C$8:$C$88,'Mai 2027'!$A$8:$A$88,$A13)) | J13: =IF($A13="","",SUMIFS('Juin 2027'!$C$8:$C$88,'Juin 2027'!$A$8:$A$88,$A13)) | K13: =IF($A13="","",SUMIFS('Juillet 2027'!$C$8:$C$88,'Juillet 2027'!$A$8:$A$88,$A13)) | L13: =IF($A13="","",SUMIFS('Août 2027'!$C$8:$C$88,'Août 2027'!$A$8:$A$88,$A13)) | M13: =IF($A13="","",SUMIFS('Septembre 2027'!$C$8:$C$88,'Septembre 2027'!$A$8:$A$88,$A13)) | N13: =IF($A13="","",SUM(B13:M13)) | O13: =IF($A13="","",N13/12)
A14: =IF(Paramètres!A13="","",Paramètres!A13) | B14: =IF($A14="","",SUMIFS('Octobre 2026'!$C$8:$C$88,'Octobre 2026'!$A$8:$A$88,$A14)) | C14: =IF($A14="","",SUMIFS('Novembre 2026'!$C$8:$C$88,'Novembre 2026'!$A$8:$A$88,$A14)) | D14: =IF($A14="","",SUMIFS('Décembre 2026'!$C$8:$C$88,'Décembre 2026'!$A$8:$A$88,$A14)) | E14: =IF($A14="","",SUMIFS('Janvier 2027'!$C$8:$C$88,'Janvier 2027'!$A$8:$A$88,$A14)) | F14: =IF($A14="","",SUMIFS('Février 2027'!$C$8:$C$88,'Février 2027'!$A$8:$A$88,$A14)) | G14: =IF($A14="","",SUMIFS('Mars 2027'!$C$8:$C$88,'Mars 2027'!$A$8:$A$88,$A14)) | H14: =IF($A14="","",SUMIFS('Avril 2027'!$C$8:$C$88,'Avril 2027'!$A$8:$A$88,$A14)) | I14: =IF($A14="","",SUMIFS('Mai 2027'!$C$8:$C$88,'Mai 2027'!$A$8:$A$88,$A14)) | J14: =IF($A14="","",SUMIFS('Juin 2027'!$C$8:$C$88,'Juin 2027'!$A$8:$A$88,$A14)) | K14: =IF($A14="","",SUMIFS('Juillet 2027'!$C$8:$C$88,'Juillet 2027'!$A$8:$A$88,$A14)) | L14: =IF($A14="","",SUMIFS('Août 2027'!$C$8:$C$88,'Août 2027'!$A$8:$A$88,$A14)) | M14: =IF($A14="","",SUMIFS('Septembre 2027'!$C$8:$C$88,'Septembre 2027'!$A$8:$A$88,$A14)) | N14: =IF($A14="","",SUM(B14:M14)) | O14: =IF($A14="","",N14/12)
A15: =IF(Paramètres!A14="","",Paramètres!A14) | B15: =IF($A15="","",SUMIFS('Octobre 2026'!$C$8:$C$88,'Octobre 2026'!$A$8:$A$88,$A15)) | C15: =IF($A15="","",SUMIFS('Novembre 2026'!$C$8:$C$88,'Novembre 2026'!$A$8:$A$88,$A15)) | D15: =IF($A15="","",SUMIFS('Décembre 2026'!$C$8:$C$88,'Décembre 2026'!$A$8:$A$88,$A15)) | E15: =IF($A15="","",SUMIFS('Janvier 2027'!$C$8:$C$88,'Janvier 2027'!$A$8:$A$88,$A15)) | F15: =IF($A15="","",SUMIFS('Février 2027'!$C$8:$C$88,'Février 2027'!$A$8:$A$88,$A15)) | G15: =IF($A15="","",SUMIFS('Mars 2027'!$C$8:$C$88,'Mars 2027'!$A$8:$A$88,$A15)) | H15: =IF($A15="","",SUMIFS('Avril 2027'!$C$8:$C$88,'Avril 2027'!$A$8:$A$88,$A15)) | I15: =IF($A15="","",SUMIFS('Mai 2027'!$C$8:$C$88,'Mai 2027'!$A$8:$A$88,$A15)) | J15: =IF($A15="","",SUMIFS('Juin 2027'!$C$8:$C$88,'Juin 2027'!$A$8:$A$88,$A15)) | K15: =IF($A15="","",SUMIFS('Juillet 2027'!$C$8:$C$88,'Juillet 2027'!$A$8:$A$88,$A15)) | L15: =IF($A15="","",SUMIFS('Août 2027'!$C$8:$C$88,'Août 2027'!$A$8:$A$88,$A15)) | M15: =IF($A15="","",SUMIFS('Septembre 2027'!$C$8:$C$88,'Septembre 2027'!$A$8:$A$88,$A15)) | N15: =IF($A15="","",SUM(B15:M15)) | O15: =IF($A15="","",N15/12)
A16: =IF(Paramètres!A15="","",Paramètres!A15) | B16: =IF($A16="","",SUMIFS('Octobre 2026'!$C$8:$C$88,'Octobre 2026'!$A$8:$A$88,$A16)) | C16: =IF($A16="","",SUMIFS('Novembre 2026'!$C$8:$C$88,'Novembre 2026'!$A$8:$A$88,$A16)) | D16: =IF($A16="","",SUMIFS('Décembre 2026'!$C$8:$C$88,'Décembre 2026'!$A$8:$A$88,$A16)) | E16: =IF($A16="","",SUMIFS('Janvier 2027'!$C$8:$C$88,'Janvier 2027'!$A$8:$A$88,$A16)) | F16: =IF($A16="","",SUMIFS('Février 2027'!$C$8:$C$88,'Février 2027'!$A$8:$A$88,$A16)) | G16: =IF($A16="","",SUMIFS('Mars 2027'!$C$8:$C$88,'Mars 2027'!$A$8:$A$88,$A16)) | H16: =IF($A16="","",SUMIFS('Avril 2027'!$C$8:$C$88,'Avril 2027'!$A$8:$A$88,$A16)) | I16: =IF($A16="","",SUMIFS('Mai 2027'!$C$8:$C$88,'Mai 2027'!$A$8:$A$88,$A16)) | J16: =IF($A16="","",SUMIFS('Juin 2027'!$C$8:$C$88,'Juin 2027'!$A$8:$A$88,$A16)) | K16: =IF($A16="","",SUMIFS('Juillet 2027'!$C$8:$C$88,'Juillet 2027'!$A$8:$A$88,$A16)) | L16: =IF($A16="","",SUMIFS('Août 2027'!$C$8:$C$88,'Août 2027'!$A$8:$A$88,$A16)) | M16: =IF($A16="","",SUMIFS('Septembre 2027'!$C$8:$C$88,'Septembre 2027'!$A$8:$A$88,$A16)) | N16: =IF($A16="","",SUM(B16:M16)) | O16: =IF($A16="","",N16/12)
... A34: =IF(Paramètres!A33="","",Paramètres!A33) | B34: =IF($A34="","",SUMIFS('Octobre 2026'!$C$8:$C$88,'Octobre 2026'!$A$8:$A$88,$A34)) | C34: =IF($A34="","",SUMIFS('Novembre 2026'!$C$8:$C$88,'Novembre 2026'!$A$8:$A$88,$A34)) | D34: =IF($A34="","",SUMIFS('Décembre 2026'!$C$8:$C$88,'Décembre 2026'!$A$8:$A$88,$A34)) | E34: =IF($A34="","",SUMIFS('Janvier 2027'!$C$8:$C$88,'Janvier 2027'!$A$8:$A$88,$A34)) | F34: =IF($A34="","",SUMIFS('Février 2027'!$C$8:$C$88,'Février 2027'!$A$8:$A$88,$A34)) | G34: =IF($A34="","",SUMIFS('Mars 2027'!$C$8:$C$88,'Mars 2027'!$A$8:$A$88,$A34)) | H34: =IF($A34="","",SUMIFS('Avril 2027'!$C$8:$C$88,'Avril 2027'!$A$8:$A$88,$A34)) | I34: =IF($A34="","",SUMIFS('Mai 2027'!$C$8:$C$88,'Mai 2027'!$A$8:$A$88,$A34)) | J34: =IF($A34="","",SUMIFS('Juin 2027'!$C$8:$C$88,'Juin 2027'!$A$8:$A$88,$A34)) | K34: =IF($A34="","",SUMIFS('Juillet 2027'!$C$8:$C$88,'Juillet 2027'!$A$8:$A$88,$A34)) | L34: =IF($A34="","",SUMIFS('Août 2027'!$C$8:$C$88,'Août 2027'!$A$8:$A$88,$A34)) | M34: =IF($A34="","",SUMIFS('Septembre 2027'!$C$8:$C$88,'Septembre 2027'!$A$8:$A$88,$A34)) | N34: =IF($A34="","",SUM(B34:M34)) | O34: =IF($A34="","",N34/12)
A35: Sans catégorie | B35: ='Octobre 2026'!$B$3-SUM(B5:B34) | C35: ='Novembre 2026'!$B$3-SUM(C5:C34) | D35: ='Décembre 2026'!$B$3-SUM(D5:D34) | E35: ='Janvier 2027'!$B$3-SUM(E5:E34) | F35: ='Février 2027'!$B$3-SUM(F5:F34) | G35: ='Mars 2027'!$B$3-SUM(G5:G34) | H35: ='Avril 2027'!$B$3-SUM(H5:H34) | I35: ='Mai 2027'!$B$3-SUM(I5:I34) | J35: ='Juin 2027'!$B$3-SUM(J5:J34) | K35: ='Juillet 2027'!$B$3-SUM(K5:K34) | L35: ='Août 2027'!$B$3-SUM(L5:L34) | M35: ='Septembre 2027'!$B$3-SUM(M5:M34) | N35: =SUM(B35:M35) | O35: =N35/12
A36: TOTAL DU MOIS | B36: ='Octobre 2026'!$B$3 | C36: ='Novembre 2026'!$B$3 | D36: ='Décembre 2026'!$B$3 | E36: ='Janvier 2027'!$B$3 | F36: ='Février 2027'!$B$3 | G36: ='Mars 2027'!$B$3 | H36: ='Avril 2027'!$B$3 | I36: ='Mai 2027'!$B$3 | J36: ='Juin 2027'!$B$3 | K36: ='Juillet 2027'!$B$3 | L36: ='Août 2027'!$B$3 | M36: ='Septembre 2027'!$B$3 | N36: =SUM(B36:M36) | O36: =N36/12
A37: Déjà payé | B37: ='Octobre 2026'!$B$4 | C37: ='Novembre 2026'!$B$4 | D37: ='Décembre 2026'!$B$4 | E37: ='Janvier 2027'!$B$4 | F37: ='Février 2027'!$B$4 | G37: ='Mars 2027'!$B$4 | H37: ='Avril 2027'!$B$4 | I37: ='Mai 2027'!$B$4 | J37: ='Juin 2027'!$B$4 | K37: ='Juillet 2027'!$B$4 | L37: ='Août 2027'!$B$4 | M37: ='Septembre 2027'!$B$4 | N37: =SUM(B37:M37) | O37: =N37/12
A38: Reste à payer | B38: ='Octobre 2026'!$B$5 | C38: ='Novembre 2026'!$B$5 | D38: ='Décembre 2026'!$B$5 | E38: ='Janvier 2027'!$B$5 | F38: ='Février 2027'!$B$5 | G38: ='Mars 2027'!$B$5 | H38: ='Avril 2027'!$B$5 | I38: ='Mai 2027'!$B$5 | J38: ='Juin 2027'!$B$5 | K38: ='Juillet 2027'!$B$5 | L38: ='Août 2027'!$B$5 | M38: ='Septembre 2027'!$B$5 | N38: =SUM(B38:M38) | O38: =N38/12

Sheet Paramètres
A1: Listes utilisées par les menus déroulants (vous pouvez ajouter / renommer)
A3: Catégories | B3: Fréquences | C3: Modes de paiement | D3: Mois | E3: Payé ?
A4: Logement (loyer, garage, charges) | B4: Mensuel | C4: Prélèvement | D4: Janvier | E4: Oui
A5: Énergie & eau | B5: Trimestriel | C5: Virement | D5: Février | E5: Non
A6: Téléphone & Internet | B6: Semestriel | C6: Carte bancaire | D6: Mars
A7: Assurances | B7: Annuel | C7: Espèces | D7: Avril
A8: Santé (hôpital, médecin, pharmacie) | C8: Chèque | D8: Mai
A9: Transport & voiture | C9: PayPal | D9: Juin
A10: Abonnements (TV, streaming, sport…) | D10: Juillet
A11: Crédits & prêts | D11: Août
A12: Impôts & taxes | D12: Septembre
A13: Banque (frais, cartes) | D13: Octobre
A14: Business / Dropshipping | D14: Novembre
A15: Publicité (Google, Meta, TikTok Ads) | D15: Décembre
A16: Courses & alimentation
A17: Divers

Sheet Charges fixes
A1: Charges fixes & abonnements (à saisir une seule fois)
A2: Chaque ligne est recopiée automatiquement dans les 12 onglets mensuels, selon sa fréquence. Cellules jaunes = à remplir.
A3: Coût moyen par mois : | D3: =SUM(J6:J55)
A5: Catégorie | B5: Libellé | C5: Montant (€) | D5: Fréquence | E5: Mois du 1er paiement (si pas mensuel) | F5: Jour du paiement (1-31) | G5: Mode de paiement | H5: Organisme / compte | I5: Remarques | J5: Coût moyen / mois (€) | K5: N° mois (auto)
A6: Logement (loyer, garage, charges) | B6: Loyer | D6: Mensuel | J6: =IF(B6="","",N(C6)*IF(D6="Trimestriel",1/3,IF(D6="Semestriel",1/6,IF(D6="Annuel",1/12,1)))) | K6: =IFERROR(MATCH(E6,Paramètres!$D$4:$D$15,0),0)
A7: Logement (loyer, garage, charges) | B7: Garage / parking | D7: Mensuel | J7: =IF(B7="","",N(C7)*IF(D7="Trimestriel",1/3,IF(D7="Semestriel",1/6,IF(D7="Annuel",1/12,1)))) | K7: =IFERROR(MATCH(E7,Paramètres!$D$4:$D$15,0),0)
A8: Logement (loyer, garage, charges) | B8: Charges de copropriété | D8: Mensuel | J8: =IF(B8="","",N(C8)*IF(D8="Trimestriel",1/3,IF(D8="Semestriel",1/6,IF(D8="Annuel",1/12,1)))) | K8: =IFERROR(MATCH(E8,Paramètres!$D$4:$D$15,0),0)
A9: Énergie & eau | B9: Électricité | D9: Mensuel | J9: =IF(B9="","",N(C9)*IF(D9="Trimestriel",1/3,IF(D9="Semestriel",1/6,IF(D9="Annuel",1/12,1)))) | K9: =IFERROR(MATCH(E9,Paramètres!$D$4:$D$15,0),0)
A10: Énergie & eau | B10: Gaz | D10: Mensuel | J10: =IF(B10="","",N(C10)*IF(D10="Trimestriel",1/3,IF(D10="Semestriel",1/6,IF(D10="Annuel",1/12,1)))) | K10: =IFERROR(MATCH(E10,Paramètres!$D$4:$D$15,0),0)
A11: Énergie & eau | B11: Eau | D11: Mensuel | J11: =IF(B11="","",N(C11)*IF(D11="Trimestriel",1/3,IF(D11="Semestriel",1/6,IF(D11="Annuel",1/12,1)))) | K11: =IFERROR(MATCH(E11,Paramètres!$D$4:$D$15,0),0)
A12: Téléphone & Internet | B12: Forfait téléphone mobile | D12: Mensuel | J12: =IF(B12="","",N(C12)*IF(D12="Trimestriel",1/3,IF(D12="Semestriel",1/6,IF(D12="Annuel",1/12,1)))) | K12: =IFERROR(MATCH(E12,Paramètres!$D$4:$D$15,0),0)
A13: Téléphone & Internet | B13: Box Internet / Wifi | D13: Mensuel | J13: =IF(B13="","",N(C13)*IF(D13="Trimestriel",1/3,IF(D13="Semestriel",1/6,IF(D13="Annuel",1/12,1)))) | K13: =IFERROR(MATCH(E13,Paramètres!$D$4:$D$15,0),0)
A14: Assurances | B14: Mutuelle santé | D14: Mensuel | J14: =IF(B14="","",N(C14)*IF(D14="Trimestriel",1/3,IF(D14="Semestriel",1/6,IF(D14="Annuel",1/12,1)))) | K14: =IFERROR(MATCH(E14,Paramètres!$D$4:$D$15,0),0)
A15: Assurances | B15: Assurance auto | D15: Mensuel | J15: =IF(B15="","",N(C15)*IF(D15="Trimestriel",1/3,IF(D15="Semestriel",1/6,IF(D15="Annuel",1/12,1)))) | K15: =IFERROR(MATCH(E15,Paramètres!$D$4:$D$15,0),0)
A16: Assurances | B16: Assurance habitation | D16: Mensuel | J16: =IF(B16="","",N(C16)*IF(D16="Trimestriel",1/3,IF(D16="Semestriel",1/6,IF(D16="Annuel",1/12,1)))) | K16: =IFERROR(MATCH(E16,Paramètres!$D$4:$D$15,0),0)
A17: Assurances | B17: Assurance prêt / prévoyance | D17: Mensuel | J17: =IF(B17="","",N(C17)*IF(D17="Trimestriel",1/3,IF(D17="Semestriel",1/6,IF(D17="Annuel",1/12,1)))) | K17: =IFERROR(MATCH(E17,Paramètres!$D$4:$D$15,0),0)
... A34: Publicité (Google, Meta, TikTok Ads) | B34: TikTok Ads | D34: Mensuel | J34: =IF(B34="","",N(C34)*IF(D34="Trimestriel",1/3,IF(D34="Semestriel",1/6,IF(D34="Annuel",1/12,1)))) | K34: =IFERROR(MATCH(E34,Paramètres!$D$4:$D$15,0),0)
J35: =IF(B35="","",N(C35)*IF(D35="Trimestriel",1/3,IF(D35="Semestriel",1/6,IF(D35="Annuel",1/12,1)))) | K35: =IFERROR(MATCH(E35,Paramètres!$D$4:$D$15,0),0)
J36: =IF(B36="","",N(C36)*IF(D36="Trimestriel",1/3,IF(D36="Semestriel",1/6,IF(D36="Annuel",1/12,1)))) | K36: =IFERROR(MATCH(E36,Paramètres!$D$4:$D$15,0),0)
J37: =IF(B37="","",N(C37)*IF(D37="Trimestriel",1/3,IF(D37="Semestriel",1/6,IF(D37="Annuel",1/12,1)))) | K37: =IFERROR(MATCH(E37,Paramètres!$D$4:$D$15,0),0)
J38: =IF(B38="","",N(C38)*IF(D38="Trimestriel",1/3,IF(D38="Semestriel",1/6,IF(D38="Annuel",1/12,1)))) | K38: =IFERROR(MATCH(E38,Paramètres!$D$4:$D$15,0),0)
J39: =IF(B39="","",N(C39)*IF(D39="Trimestriel",1/3,IF(D39="Semestriel",1/6,IF(D39="Annuel",1/12,1)))) | K39: =IFERROR(MATCH(E39,Paramètres!$D$4:$D$15,0),0)
J40: =IF(B40="","",N(C40)*IF(D40="Trimestriel",1/3,IF(D40="Semestriel",1/6,IF(D40="Annuel",1/12,1)))) | K40: =IFERROR(MATCH(E40,Paramètres!$D$4:$D$15,0),0)
J41: =IF(B41="","",N(C41)*IF(D41="Trimestriel",1/3,IF(D41="Semestriel",1/6,IF(D41="Annuel",1/12,1)))) | K41: =IFERROR(MATCH(E41,Paramètres!$D$4:$D$15,0),0)
J42: =IF(B42="","",N(C42)*IF(D42="Trimestriel",1/3,IF(D42="Semestriel",1/6,IF(D42="Annuel",1/12,1)))) | K42: =IFERROR(MATCH(E42,Paramètres!$D$4:$D$15,0),0)
J43: =IF(B43="","",N(C43)*IF(D43="Trimestriel",1/3,IF(D43="Semestriel",1/6,IF(D43="Annuel",1/12,1)))) | K43: =IFERROR(MATCH(E43,Paramètres!$D$4:$D$15,0),0)
J44: =IF(B44="","",N(C44)*IF(D44="Trimestriel",1/3,IF(D44="Semestriel",1/6,IF(D44="Annuel",1/12,1)))) | K44: =IFERROR(MATCH(E44,Paramètres!$D$4:$D$15,0),0)
J45: =IF(B45="","",N(C45)*IF(D45="Trimestriel",1/3,IF(D45="Semestriel",1/6,IF(D45="Annuel",1/12,1)))) | K45: =IFERROR(MATCH(E45,Paramètres!$D$4:$D$15,0),0)
J46: =IF(B46="","",N(C46)*IF(D46="Trimestriel",1/3,IF(D46="Semestriel",1/6,IF(D46="Annuel",1/12,1)))) | K46: =IFERROR(MATCH(E46,Paramètres!$D$4:$D$15,0),0)
... J55: =IF(B55="","",N(C55)*IF(D55="Trimestriel",1/3,IF(D55="Semestriel",1/6,IF(D55="Annuel",1/12,1)))) | K55: =IFERROR(MATCH(E55,Paramètres!$D$4:$D$15,0),0)
A56: TOTAL | J56: =SUM(J6:J55)

Sheet Octobre 2026
A1: Dépenses — Octobre 2026
A2: Mois : | B2: 46296
A3: Total du mois | B3: =SUM(C8:C88) | D3: Rouge = date passée et pas encore payé · Orange = à payer dans les 7 jours
A4: Déjà payé | B4: =SUMIFS(C8:C88,F8:F88,"Oui") | D4: Colonne « Payé ? » : choisissez Oui quand le montant est sorti du compte.
A5: Reste à payer | B5: =B3-B4
A7: Catégorie | B7: Libellé | C7: Montant (€) | D7: Date de paiement / prélèvement | E7: Mode de paiement | F7: Payé ? | G7: Remarques
A8: =IF('Charges fixes'!$B$6="","",'Charges fixes'!$A$6&"") | B8: =IF('Charges fixes'!$B$6="","",'Charges fixes'!$B$6) | C8: =IF('Charges fixes'!$B$6="","",IF(OR('Charges fixes'!$D$6="Mensuel",'Charges fixes'!$D$6="",AND('Charges fixes'!$K$6>0,OR(AND('Charges fixes'!$D$6="Trimestriel",MOD(MONTH($B$2)-'Charges fixes'!$K$6+12,3)=0),AND('Charges fixes'!$D$6="Semestriel",MOD(MONTH($B$2)-'Charges fixes'!$K$6+12,6)=0),AND('Charges fixes'!$D$6="Annuel",MONTH($B$2)='Charges fixes'!$K$6)))),N('Charges fixes'!$C$6),0)) | D8: =IF(OR('Charges fixes'!$B$6="",'Charges fixes'!$F$6="",N(C8)=0),"",DATE(YEAR($B$2),MONTH($B$2),MIN('Charges fixes'!$F$6,DAY(EOMONTH($B$2,0))))) | E8: =IF('Charges fixes'!$B$6="","",'Charges fixes'!$G$6&"")
A9: =IF('Charges fixes'!$B$7="","",'Charges fixes'!$A$7&"") | B9: =IF('Charges fixes'!$B$7="","",'Charges fixes'!$B$7) | C9: =IF('Charges fixes'!$B$7="","",IF(OR('Charges fixes'!$D$7="Mensuel",'Charges fixes'!$D$7="",AND('Charges fixes'!$K$7>0,OR(AND('Charges fixes'!$D$7="Trimestriel",MOD(MONTH($B$2)-'Charges fixes'!$K$7+12,3)=0),AND('Charges fixes'!$D$7="Semestriel",MOD(MONTH($B$2)-'Charges fixes'!$K$7+12,6)=0),AND('Charges fixes'!$D$7="Annuel",MONTH($B$2)='Charges fixes'!$K$7)))),N('Charges fixes'!$C$7),0)) | D9: =IF(OR('Charges fixes'!$B$7="",'Charges fixes'!$F$7="",N(C9)=0),"",DATE(YEAR($B$2),MONTH($B$2),MIN('Charges fixes'!$F$7,DAY(EOMONTH($B$2,0))))) | E9: =IF('Charges fixes'!$B$7="","",'Charges fixes'!$G$7&"")
A10: =IF('Charges fixes'!$B$8="","",'Charges fixes'!$A$8&"") | B10: =IF('Charges fixes'!$B$8="","",'Charges fixes'!$B$8) | C10: =IF('Charges fixes'!$B$8="","",IF(OR('Charges fixes'!$D$8="Mensuel",'Charges fixes'!$D$8="",AND('Charges fixes'!$K$8>0,OR(AND('Charges fixes'!$D$8="Trimestriel",MOD(MONTH($B$2)-'Charges fixes'!$K$8+12,3)=0),AND('Charges fixes'!$D$8="Semestriel",MOD(MONTH($B$2)-'Charges fixes'!$K$8+12,6)=0),AND('Charges fixes'!$D$8="Annuel",MONTH($B$2)='Charges fixes'!$K$8)))),N('Charges fixes'!$C$8),0)) | D10: =IF(OR('Charges fixes'!$B$8="",'Charges fixes'!$F$8="",N(C10)=0),"",DATE(YEAR($B$2),MONTH($B$2),MIN('Charges fixes'!$F$8,DAY(EOMONTH($B$2,0))))) | E10: =IF('Charges fixes'!$B$8="","",'Charges fixes'!$G$8&"")
A11: =IF('Charges fixes'!$B$9="","",'Charges fixes'!$A$9&"") | B11: =IF('Charges fixes'!$B$9="","",'Charges fixes'!$B$9) | C11: =IF('Charges fixes'!$B$9="","",IF(OR('Charges fixes'!$D$9="Mensuel",'Charges fixes'!$D$9="",AND('Charges fixes'!$K$9>0,OR(AND('Charges fixes'!$D$9="Trimestriel",MOD(MONTH($B$2)-'Charges fixes'!$K$9+12,3)=0),AND('Charges fixes'!$D$9="Semestriel",MOD(MONTH($B$2)-'Charges fixes'!$K$9+12,6)=0),AND('Charges fixes'!$D$9="Annuel",MONTH($B$2)='Charges fixes'!$K$9)))),N('Charges fixes'!$C$9),0)) | D11: =IF(OR('Charges fixes'!$B$9="",'Charges fixes'!$F$9="",N(C11)=0),"",DATE(YEAR($B$2),MONTH($B$2),MIN('Charges fixes'!$F$9,DAY(EOMONTH($B$2,0))))) | E11: =IF('Charges fixes'!$B$9="","",'Charges fixes'!$G$9&"")
A12: =IF('Charges fixes'!$B$10="","",'Charges fixes'!$A$10&"") | B12: =IF('Charges fixes'!$B$10="","",'Charges fixes'!$B$10) | C12: =IF('Charges fixes'!$B$10="","",IF(OR('Charges fixes'!$D$10="Mensuel",'Charges fixes'!$D$10="",AND('Charges fixes'!$K$10>0,OR(AND('Charges fixes'!$D$10="Trimestriel",MOD(MONTH($B$2)-'Charges fixes'!$K$10+12,3)=0),AND('Charges fixes'!$D$10="Semestriel",MOD(MONTH($B$2)-'Charges fixes'!$K$10+12,6)=0),AND('Charges fixes'!$D$10="Annuel",MONTH($B$2)='Charges fixes'!$K$10)))),N('Charges fixes'!$C$10),0)) | D12: =IF(OR('Charges fixes'!$B$10="",'Charges fixes'!$F$10="",N(C12)=0),"",DATE(YEAR($B$2),MONTH($B$2),MIN('Charges fixes'!$F$10,DAY(EOMONTH($B$2,0))))) | E12: =IF('Charges fixes'!$B$10="","",'Charges fixes'!$G$10&"")
A13: =IF('Charges fixes'!$B$11="","",'Charges fixes'!$A$11&"") | B13: =IF('Charges fixes'!$B$11="","",'Charges fixes'!$B$11) | C13: =IF('Charges fixes'!$B$11="","",IF(OR('Charges fixes'!$D$11="Mensuel",'Charges fixes'!$D$11="",AND('Charges fixes'!$K$11>0,OR(AND('Charges fixes'!$D$11="Trimestriel",MOD(MONTH($B$2)-'Charges fixes'!$K$11+12,3)=0),AND('Charges fixes'!$D$11="Semestriel",MOD(MONTH($B$2)-'Charges fixes'!$K$11+12,6)=0),AND('Charges fixes'!$D$11="Annuel",MONTH($B$2)='Charges fixes'!$K$11)))),N('Charges fixes'!$C$11),0)) | D13: =IF(OR('Charges fixes'!$B$11="",'Charges fixes'!$F$11="",N(C13)=0),"",DATE(YEAR($B$2),MONTH($B$2),MIN('Charges fixes'!$F$11,DAY(EOMONTH($B$2,0))))) | E13: =IF('Charges fixes'!$B$11="","",'Charges fixes'!$G$11&"")
A14: =IF('Charges fixes'!$B$12="","",'Charges fixes'!$A$12&"") | B14: =IF('Charges fixes'!$B$12="","",'Charges fixes'!$B$12) | C14: =IF('Charges fixes'!$B$12="","",IF(OR('Charges fixes'!$D$12="Mensuel",'Charges fixes'!$D$12="",AND('Charges fixes'!$K$12>0,OR(AND('Charges fixes'!$D$12="Trimestriel",MOD(MONTH($B$2)-'Charges fixes'!$K$12+12,3)=0),AND('Charges fixes'!$D$12="Semestriel",MOD(MONTH($B$2)-'Charges fixes'!$K$12+12,6)=0),AND('Charges fixes'!$D$12="Annuel",MONTH($B$2)='Charges fixes'!$K$12)))),N('Charges fixes'!$C$12),0)) | D14: =IF(OR('Charges fixes'!$B$12="",'Charges fixes'!$F$12="",N(C14)=0),"",DATE(YEAR($B$2),MONTH($B$2),MIN('Charges fixes'!$F$12,DAY(EOMONTH($B$2,0))))) | E14: =IF('Charges fixes'!$B$12="","",'Charges fixes'!$G$12&"")
A15: =IF('Charges fixes'!$B$13="","",'Charges fixes'!$A$13&"") | B15: =IF('Charges fixes'!$B$13="","",'Charges fixes'!$B$13) | C15: =IF('Charges fixes'!$B$13="","",IF(OR('Charges fixes'!$D$13="Mensuel",'Charges fixes'!$D$13="",AND('Charges fixes'!$K$13>0,OR(AND('Charges fixes'!$D$13="Trimestriel",MOD(MONTH($B$2)-'Charges fixes'!$K$13+12,3)=0),AND('Charges fixes'!$D$13="Semestriel",MOD(MONTH($B$2)-'Charges fixes'!$K$13+12,6)=0),AND('Charges fixes'!$D$13="Annuel",MONTH($B$2)='Charges fixes'!$K$13)))),N('Charges fixes'!$C$13),0)) | D15: =IF(OR('Charges fixes'!$B$13="",'Charges fixes'!$F$13="",N(C15)=0),"",DATE(YEAR($B$2),MONTH($B$2),MIN('Charges fixes'!$F$13,DAY(EOMONTH($B$2,0))))) | E15: =IF('Charges fixes'!$B$13="","",'Charges fixes'!$G$13&"")
A16: =IF('Charges fixes'!$B$14="","",'Charges fixes'!$A$14&"") | B16: =IF('Charges fixes'!$B$14="","",'Charges fixes'!$B$14) | C16: =IF('Charges fixes'!$B$14="","",IF(OR('Charges fixes'!$D$14="Mensuel",'Charges fixes'!$D$14="",AND('Charges fixes'!$K$14>0,OR(AND('Charges fixes'!$D$14="Trimestriel",MOD(MONTH($B$2)-'Charges fixes'!$K$14+12,3)=0),AND('Charges fixes'!$D$14="Semestriel",MOD(MONTH($B$2)-'Charges fixes'!$K$14+12,6)=0),AND('Charges fixes'!$D$14="Annuel",MONTH($B$2)='Charges fixes'!$K$14)))),N('Charges fixes'!$C$14),0)) | D16: =IF(OR('Charges fixes'!$B$14="",'Charges fixes'!$F$14="",N(C16)=0),"",DATE(YEAR($B$2),MONTH($B$2),MIN('Charges fixes'!$F$14,DAY(EOMONTH($B$2,0))))) | E16: =IF('Charges fixes'!$B$14="","",'Charges fixes'!$G$14&"")
A17: =IF('Charges fixes'!$B$15="","",'Charges fixes'!$A$15&"") | B17: =IF('Charges fixes'!$B$15="","",'Charges fixes'!$B$15) | C17: =IF('Charges fixes'!$B$15="","",IF(OR('Charges fixes'!$D$15="Mensuel",'Charges fixes'!$D$15="",AND('Charges fixes'!$K$15>0,OR(AND('Charges fixes'!$D$15="Trimestriel",MOD(MONTH($B$2)-'Charges fixes'!$K$15+12,3)=0),AND('Charges fixes'!$D$15="Semestriel",MOD(MONTH($B$2)-'Charges fixes'!$K$15+12,6)=0),AND('Charges fixes'!$D$15="Annuel",MONTH($B$2)='Charges fixes'!$K$15)))),N('Charges fixes'!$C$15),0)) | D17: =IF(OR('Charges fixes'!$B$15="",'Charges fixes'!$F$15="",N(C17)=0),"",DATE(YEAR($B$2),MONTH($B$2),MIN('Charges fixes'!$F$15,DAY(EOMONTH($B$2,0))))) | E17: =IF('Charges fixes'!$B$15="","",'Charges fixes'!$G$15&"")
A18: =IF('Charges fixes'!$B$16="","",'Charges fixes'!$A$16&"") | B18: =IF('Charges fixes'!$B$16="","",'Charges fixes'!$B$16) | C18: =IF('Charges fixes'!$B$16="","",IF(OR('Charges fixes'!$D$16="Mensuel",'Charges fixes'!$D$16="",AND('Charges fixes'!$K$16>0,OR(AND('Charges fixes'!$D$16="Trimestriel",MOD(MONTH($B$2)-'Charges fixes'!$K$16+12,3)=0),AND('Charges fixes'!$D$16="Semestriel",MOD(MONTH($B$2)-'Charges fixes'!$K$16+12,6)=0),AND('Charges fixes'!$D$16="Annuel",MONTH($B$2)='Charges fixes'!$K$16)))),N('Charges fixes'!$C$16),0)) | D18: =IF(OR('Charges fixes'!$B$16="",'Charges fixes'!$F$16="",N(C18)=0),"",DATE(YEAR($B$2),MONTH($B$2),MIN('Charges fixes'!$F$16,DAY(EOMONTH($B$2,0))))) | E18: =IF('Charges fixes'!$B$16="","",'Charges fixes'!$G$16&"")
A19: =IF('Charges fixes'!$B$17="","",'Charges fixes'!$A$17&"") | B19: =IF('Charges fixes'!$B$17="","",'Charges fixes'!$B$17) | C19: =IF('Charges fixes'!$B$17="","",IF(OR('Charges fixes'!$D$17="Mensuel",'Charges fixes'!$D$17="",AND('Charges fixes'!$K$17>0,OR(AND('Charges fixes'!$D$17="Trimestriel",MOD(MONTH($B$2)-'Charges fixes'!$K$17+12,3)=0),AND('Charges fixes'!$D$17="Semestriel",MOD(MONTH($B$2)-'Charges fixes'!$K$17+12,6)=0),AND('Charges fixes'!$D$17="Annuel",MONTH($B$2)='Charges fixes'!$K$17)))),N('Charges fixes'!$C$17),0)) | D19: =IF(OR('Charges fixes'!$B$17="",'Charges fixes'!$F$17="",N(C19)=0),"",DATE(YEAR($B$2),MONTH($B$2),MIN('Charges fixes'!$F$17,DAY(EOMONTH($B$2,0))))) | E19: =IF('Charges fixes'!$B$17="","",'Charges fixes'!$G$17&"")
A20: =IF('Charges fixes'!$B$18="","",'Charges fixes'!$A$18&"") | B20: =IF('Charges fixes'!$B$18="","",'Charges fixes'!$B$18) | C20: =IF('Charges fixes'!$B$18="","",IF(OR('Charges fixes'!$D$18="Mensuel",'Charges fixes'!$D$18="",AND('Charges fixes'!$K$18>0,OR(AND('Charges fixes'!$D$18="Trimestriel",MOD(MONTH($B$2)-'Charges fixes'!$K$18+12,3)=0),AND('Charges fixes'!$D$18="Semestriel",MOD(MONTH($B$2)-'Charges fixes'!$K$18+12,6)=0),AND('Charges fixes'!$D$18="Annuel",MONTH($B$2)='Charges fixes'!$K$18)))),N('Charges fixes'!$C$18),0)) | D20: =IF(OR('Charges fixes'!$B$18="",'Charges fixes'!$F$18="",N(C20)=0),"",DATE(YEAR($B$2),MONTH($B$2),MIN('Charges fixes'!$F$18,DAY(EOMONTH($B$2,0))))) | E20: =IF('Charges fixes'!$B$18="","",'Charges fixes'!$G$18&"")
A21: =IF('Charges fixes'!$B$19="","",'Charges fixes'!$A$19&"") | B21: =IF('Charges fixes'!$B$19="","",'Charges fixes'!$B$19) | C21: =IF('Charges fixes'!$B$19="","",IF(OR('Charges fixes'!$D$19="Mensuel",'Charges fixes'!$D$19="",AND('Charges fixes'!$K$19>0,OR(AND('Charges fixes'!$D$19="Trimestriel",MOD(MONTH($B$2)-'Charges fixes'!$K$19+12,3)=0),AND('Charges fixes'!$D$19="Semestriel",MOD(MONTH($B$2)-'Charges fixes'!$K$19+12,6)=0),AND('Charges fixes'!$D$19="Annuel",MONTH($B$2)='Charges fixes'!$K$19)))),N('Charges fixes'!$C$19),0)) | D21: =IF(OR('Charges fixes'!$B$19="",'Charges fixes'!$F$19="",N(C21)=0),"",DATE(YEAR($B$2),MONTH($B$2),MIN('Charges fixes'!$F$19,DAY(EOMONTH($B$2,0))))) | E21: =IF('Charges fixes'!$B$19="","",'Charges fixes'!$G$19&"")
A22: =IF('Charges fixes'!$B$20="","",'Charges fixes'!$A$20&"") | B22: =IF('Charges fixes'!$B$20="","",'Charges fixes'!$B$20) | C22: =IF('Charges fixes'!$B$20="","",IF(OR('Charges fixes'!$D$20="Mensuel",'Charges fixes'!$D$20="",AND('Charges fixes'!$K$20>0,OR(AND('Charges fixes'!$D$20="Trimestriel",MOD(MONTH($B$2)-'Charges fixes'!$K$20+12,3)=0),AND('Charges fixes'!$D$20="Semestriel",MOD(MONTH($B$2)-'Charges fixes'!$K$20+12,6)=0),AND('Charges fixes'!$D$20="Annuel",MONTH($B$2)='Charges fixes'!$K$20)))),N('Charges fixes'!$C$20),0)) | D22: =IF(OR('Charges fixes'!$B$20="",'Charges fixes'!$F$20="",N(C22)=0),"",DATE(YEAR($B$2),MONTH($B$2),MIN('Charges fixes'!$F$20,DAY(EOMONTH($B$2,0))))) | E22: =IF('Charges fixes'!$B$20="","",'Charges fixes'!$G$20&"")
A23: =IF('Charges fixes'!$B$21="","",'Charges fixes'!$A$21&"") | B23: =IF('Charges fixes'!$B$21="","",'Charges fixes'!$B$21) | C23: =IF('Charges fixes'!$B$21="","",IF(OR('Charges fixes'!$D$21="Mensuel",'Charges fixes'!$D$21="",AND('Charges fixes'!$K$21>0,OR(AND('Charges fixes'!$D$21="Trimestriel",MOD(MONTH($B$2)-'Charges fixes'!$K$21+12,3)=0),AND('Charges fixes'!$D$21="Semestriel",MOD(MONTH($B$2)-'Charges fixes'!$K$21+12,6)=0),AND('Charges fixes'!$D$21="Annuel",MONTH($B$2)='Charges fixes'!$K$21)))),N('Charges fixes'!$C$21),0)) | D23: =IF(OR('Charges fixes'!$B$21="",'Charges fixes'!$F$21="",N(C23)=0),"",DATE(YEAR($B$2),MONTH($B$2),MIN('Charges fixes'!$F$21,DAY(EOMONTH($B$2,0))))) | E23: =IF('Charges fixes'!$B$21="","",'Charges fixes'!$G$21&"")
A24: =IF('Charges fixes'!$B$22="","",'Charges fixes'!$A$22&"") | B24: =IF('Charges fixes'!$B$22="","",'Charges fixes'!$B$22) | C24: =IF('Charges fixes'!$B$22="","",IF(OR('Charges fixes'!$D$22="Mensuel",'Charges fixes'!$D$22="",AND('Charges fixes'!$K$22>0,OR(AND('Charges fixes'!$D$22="Trimestriel",MOD(MONTH($B$2)-'Charges fixes'!$K$22+12,3)=0),AND('Charges fixes'!$D$22="Semestriel",MOD(MONTH($B$2)-'Charges fixes'!$K$22+12,6)=0),AND('Charges fixes'!$D$22="Annuel",MONTH($B$2)='Charges fixes'!$K$22)))),N('Charges fixes'!$C$22),0)) | D24: =IF(OR('Charges fixes'!$B$22="",'Charges fixes'!$F$22="",N(C24)=0),"",DATE(YEAR($B$2),MONTH($B$2),MIN('Charges fixes'!$F$22,DAY(EOMONTH($B$2,0))))) | E24: =IF('Charges fixes'!$B$22="","",'Charges fixes'!$G$22&"")
A25: =IF('Charges fixes'!$B$23="","",'Charges fixes'!$A$23&"") | B25: =IF('Charges fixes'!$B$23="","",'Charges fixes'!$B$23) | C25: =IF('Charges fixes'!$B$23="","",IF(OR('Charges fixes'!$D$23="Mensuel",'Charges fixes'!$D$23="",AND('Charges fixes'!$K$23>0,OR(AND('Charges fixes'!$D$23="Trimestriel",MOD(MONTH($B$2)-'Charges fixes'!$K$23+12,3)=0),AND('Charges fixes'!$D$23="Semestriel",MOD(MONTH($B$2)-'Charges fixes'!$K$23+12,6)=0),AND('Charges fixes'!$D$23="Annuel",MONTH($B$2)='Charges fixes'!$K$23)))),N('Charges fixes'!$C$23),0)) | D25: =IF(OR('Charges fixes'!$B$23="",'Charges fixes'!$F$23="",N(C25)=0),"",DATE(YEAR($B$2),MONTH($B$2),MIN('Charges fixes'!$F$23,DAY(EOMONTH($B$2,0))))) | E25: =IF('Charges fixes'!$B$23="","",'Charges fixes'!$G$23&"")
A26: =IF('Charges fixes'!$B$24="","",'Charges fixes'!$A$24&"") | B26: =IF('Charges fixes'!$B$24="","",'Charges fixes'!$B$24) | C26: =IF('Charges fixes'!$B$24="","",IF(OR('Charges fixes'!$D$24="Mensuel",'Charges fixes'!$D$24="",AND('Charges fixes'!$K$24>0,OR(AND('Charges fixes'!$D$24="Trimestriel",MOD(MONTH($B$2)-'Charges fixes'!$K$24+12,3)=0),AND('Charges fixes'!$D$24="Semestriel",MOD(MONTH($B$2)-'Charges fixes'!$K$24+12,6)=0),AND('Charges fixes'!$D$24="Annuel",MONTH($B$2)='Charges fixes'!$K$24)))),N('Charges fixes'!$C$24),0)) | D26: =IF(OR('Charges fixes'!$B$24="",'Charges fixes'!$F$24="",N(C26)=0),"",DATE(YEAR($B$2),MONTH($B$2),MIN('Charges fixes'!$F$24,DAY(EOMONTH($B$2,0))))) | E26: =IF('Charges fixes'!$B$24="","",'Charges fixes'!$G$24&"")
A27: =IF('Charges fixes'!$B$25="","",'Charges fixes'!$A$25&"") | B27: =IF('Charges fixes'!$B$25="","",'Charges fixes'!$B$25) | C27: =IF('Charges fixes'!$B$25="","",IF(OR('Charges fixes'!$D$25="Mensuel",'Charges fixes'!$D$25="",AND('Charges fixes'!$K$25>0,OR(AND('Charges fixes'!$D$25="Trimestriel",MOD(MONTH($B$2)-'Charges fixes'!$K$25+12,3)=0),AND('Charges fixes'!$D$25="Semestriel",MOD(MONTH($B$2)-'Charges fixes'!$K$25+12,6)=0),AND('Charges fixes'!$D$25="Annuel",MONTH($B$2)='Charges fixes'!$K$25)))),N('Charges fixes'!$C$25),0)) | D27: =IF(OR('Charges fixes'!$B$25="",'Charges fixes'!$F$25="",N(C27)=0),"",DATE(YEAR($B$2),MONTH($B$2),MIN('Charges fixes'!$F$25,DAY(EOMONTH($B$2,0))))) | E27: =IF('Charges fixes'!$B$25="","",'Charges fixes'!$G$25&"")
A28: =IF('Charges fixes'!$B$26="","",'Charges fixes'!$A$26&"") | B28: =IF('Charges fixes'!$B$26="","",'Charges fixes'!$B$26) | C28: =IF('Charges fixes'!$B$26="","",IF(OR('Charges fixes'!$D$26="Mensuel",'Charges fixes'!$D$26="",AND('Charges fixes'!$K$26>0,OR(AND('Charges fixes'!$D$26="Trimestriel",MOD(MONTH($B$2)-'Charges fixes'!$K$26+12,3)=0),AND('Charges fixes'!$D$26="Semestriel",MOD(MONTH($B$2)-'Charges fixes'!$K$26+12,6)=0),AND('Charges fixes'!$D$26="Annuel",MONTH($B$2)='Charges fixes'!$K$26)))),N('Charges fixes'!$C$26),0)) | D28: =IF(OR('Charges fixes'!$B$26="",'Charges fixes'!$F$26="",N(C28)=0),"",DATE(YEAR($B$2),MONTH($B$2),MIN('Charges fixes'!$F$26,DAY(EOMONTH($B$2,0))))) | E28: =IF('Charges fixes'!$B$26="","",'Charges fixes'!$G$26&"")
A29: =IF('Charges fixes'!$B$27="","",'Charges fixes'!$A$27&"") | B29: =IF('Charges fixes'!$B$27="","",'Charges fixes'!$B$27) | C29: =IF('Charges fixes'!$B$27="","",IF(OR('Charges fixes'!$D$27="Mensuel",'Charges fixes'!$D$27="",AND('Charges fixes'!$K$27>0,OR(AND('Charges fixes'!$D$27="Trimestriel",MOD(MONTH($B$2)-'Charges fixes'!$K$27+12,3)=0),AND('Charges fixes'!$D$27="Semestriel",MOD(MONTH($B$2)-'Charges fixes'!$K$27+12,6)=0),AND('Charges fixes'!$D$27="Annuel",MONTH($B$2)='Charges fixes'!$K$27)))),N('Charges fixes'!$C$27),0)) | D29: =IF(OR('Charges fixes'!$B$27="",'Charges fixes'!$F$27="",N(C29)=0),"",DATE(YEAR($B$2),MONTH($B$2),MIN('Charges fixes'!$F$27,DAY(EOMONTH($B$2,0))))) | E29: =IF('Charges fixes'!$B$27="","",'Charges fixes'!$G$27&"")
A30: =IF('Charges fixes'!$B$28="","",'Charges fixes'!$A$28&"") | B30: =IF('Charges fixes'!$B$28="","",'Charges fixes'!$B$28) | C30: =IF('Charges fixes'!$B$28="","",IF(OR('Charges fixes'!$D$28="Mensuel",'Charges fixes'!$D$28="",AND('Charges fixes'!$K$28>0,OR(AND('Charges fixes'!$D$28="Trimestriel",MOD(MONTH($B$2)-'Charges fixes'!$K$28+12,3)=0),AND('Charges fixes'!$D$28="Semestriel",MOD(MONTH($B$2)-'Charges fixes'!$K$28+12,6)=0),AND('Charges fixes'!$D$28="Annuel",MONTH($B$2)='Charges fixes'!$K$28)))),N('Charges fixes'!$C$28),0)) | D30: =IF(OR('Charges fixes'!$B$28="",'Charges fixes'!$F$28="",N(C30)=0),"",DATE(YEAR($B$2),MONTH($B$2),MIN('Charges fixes'!$F$28,DAY(EOMONTH($B$2,0))))) | E30: =IF('Charges fixes'!$B$28="","",'Charges fixes'!$G$28&"")
A31: =IF('Charges fixes'!$B$29="","",'Charges fixes'!$A$29&"") | B31: =IF('Charges fixes'!$B$29="","",'Charges fixes'!$B$29) | C31: =IF('Charges fixes'!$B$29="","",IF(OR('Charges fixes'!$D$29="Mensuel",'Charges fixes'!$D$29="",AND('Charges fixes'!$K$29>0,OR(AND('Charges fixes'!$D$29="Trimestriel",MOD(MONTH($B$2)-'Charges fixes'!$K$29+12,3)=0),AND('Charges fixes'!$D$29="Semestriel",MOD(MONTH($B$2)-'Charges fixes'!$K$29+12,6)=0),AND('Charges fixes'!$D$29="Annuel",MONTH($B$2)='Charges fixes'!$K$29)))),N('Charges fixes'!$C$29),0)) | D31: =IF(OR('Charges fixes'!$B$29="",'Charges fixes'!$F$29="",N(C31)=0),"",DATE(YEAR($B$2),MONTH($B$2),MIN('Charges fixes'!$F$29,DAY(EOMONTH($B$2,0))))) | E31: =IF('Charges fixes'!$B$29="","",'Charges fixes'!$G$29&"")
A32: =IF('Charges fixes'!$B$30="","",'Charges fixes'!$A$30&"") | B32: =IF('Charges fixes'!$B$30="","",'Charges fixes'!$B$30) | C32: =IF('Charges fixes'!$B$30="","",IF(OR('Charges fixes'!$D$30="Mensuel",'Charges fixes'!$D$30="",AND('Charges fixes'!$K$30>0,OR(AND('Charges fixes'!$D$30="Trimestriel",MOD(MONTH($B$2)-'Charges fixes'!$K$30+12,3)=0),AND('Charges fixes'!$D$30="Semestriel",MOD(MONTH($B$2)-'Charges fixes'!$K$30+12,6)=0),AND('Charges fixes'!$D$30="Annuel",MONTH($B$2)='Charges fixes'!$K$30)))),N('Charges fixes'!$C$30),0)) | D32: =IF(OR('Charges fixes'!$B$30="",'Charges fixes'!$F$30="",N(C32)=0),"",DATE(YEAR($B$2),MONTH($B$2),MIN('Charges fixes'!$F$30,DAY(EOMONTH($B$2,0))))) | E32: =IF('Charges fixes'!$B$30="","",'Charges fixes'!$G$30&"")
A33: =IF('Charges fixes'!$B$31="","",'Charges fixes'!$A$31&"") | B33: =IF('Charges fixes'!$B$31="","",'Charges fixes'!$B$31) | C33: =IF('Charges fixes'!$B$31="","",IF(OR('Charges fixes'!$D$31="Mensuel",'Charges fixes'!$D$31="",AND('Charges fixes'!$K$31>0,OR(AND('Charges fixes'!$D$31="Trimestriel",MOD(MONTH($B$2)-'Charges fixes'!$K$31+12,3)=0),AND('Charges fixes'!$D$31="Semestriel",MOD(MONTH($B$2)-'Charges fixes'!$K$31+12,6)=0),AND('Charges fixes'!$D$31="Annuel",MONTH($B$2)='Charges fixes'!$K$31)))),N('Charges fixes'!$C$31),0)) | D33: =IF(OR('Charges fixes'!$B$31="",'Charges fixes'!$F$31="",N(C33)=0),"",DATE(YEAR($B$2),MONTH($B$2),MIN('Charges fixes'!$F$31,DAY(EOMONTH($B$2,0))))) | E33: =IF('Charges fixes'!$B$31="","",'Charges fixes'!$G$31&"")
A34: =IF('Charges fixes'!$B$32="","",'Charges fixes'!$A$32&"") | B34: =IF('Charges fixes'!$B$32="","",'Charges fixes'!$B$32) | C34: =IF('Charges fixes'!$B$32="","",IF(OR('Charges fixes'!$D$32="Mensuel",'Charges fixes'!$D$32="",AND('Charges fixes'!$K$32>0,OR(AND('Charges fixes'!$D$32="Trimestriel",MOD(MONTH($B$2)-'Charges fixes'!$K$32+12,3)=0),AND('Charges fixes'!$D$32="Semestriel",MOD(MONTH($B$2)-'Charges fixes'!$K$32+12,6)=0),AND('Charges fixes'!$D$32="Annuel",MONTH($B$2)='Charges fixes'!$K$32)))),N('Charges fixes'!$C$32),0)) | D34: =IF(OR('Charges fixes'!$B$32="",'Charges fixes'!$F$32="",N(C34)=0),"",DATE(YEAR($B$2),MONTH($B$2),MIN('Charges fixes'!$F$32,DAY(EOMONTH($B$2,0))))) | E34: =IF('Charges fixes'!$B$32="","",'Charges fixes'!$G$32&"")
A35: =IF('Charges fixes'!$B$33="","",'Charges fixes'!$A$33&"") | B35: =IF('Charges fixes'!$B$33="","",'Charges fixes'!$B$33) | C35: =IF('Charges fixes'!$B$33="","",IF(OR('Charges fixes'!$D$33="Mensuel",'Charges fixes'!$D$33="",AND('Charges fixes'!$K$33>0,OR(AND('Charges fixes'!$D$33="Trimestriel",MOD(MONTH($B$2)-'Charges fixes'!$K$33+12,3)=0),AND('Charges fixes'!$D$33="Semestriel",MOD(MONTH($B$2)-'Charges fixes'!$K$33+12,6)=0),AND('Charges fixes'!$D$33="Annuel",MONTH($B$2)='Charges fixes'!$K$33)))),N('Charges fixes'!$C$33),0)) | D35: =IF(OR('Charges fixes'!$B$33="",'Charges fixes'!$F$33="",N(C35)=0),"",DATE(YEAR($B$2),MONTH($B$2),MIN('Charges fixes'!$F$33,DAY(EOMONTH($B$2,0))))) | E35: =IF('Charges fixes'!$B$33="","",'Charges fixes'!$G$33&"")
A36: =IF('Charges fixes'!$B$34="","",'Charges fixes'!$A$34&"") | B36: =IF('Charges fixes'!$B$34="","",'Charges fixes'!$B$34) | C36: =IF('Charges fixes'!$B$34="","",IF(OR('Charges fixes'!$D$34="Mensuel",'Charges fixes'!$D$34="",AND('Charges fixes'!$K$34>0,OR(AND('Charges fixes'!$D$34="Trimestriel",MOD(MONTH($B$2)-'Charges fixes'!$K$34+12,3)=0),AND('Charges fixes'!$D$34="Semestriel",MOD(MONTH($B$2)-'Charges fixes'!$K$34+12,6)=0),AND('Charges fixes'!$D$34="Annuel",MONTH($B$2)='Charges fixes'!$K$34)))),N('Charges fixes'!$C$34),0)) | D36: =IF(OR('Charges fixes'!$B$34="",'Charges fixes'!$F$34="",N(C36)=0),"",DATE(YEAR($B$2),MONTH($B$2),MIN('Charges fixes'!$F$34,DAY(EOMONTH($B$2,0))))) | E36: =IF('Charges fixes'!$B$34="","",'Charges fixes'!$G$34&"")
A37: =IF('Charges fixes'!$B$35="","",'Charges fixes'!$A$35&"") | B37: =IF('Charges fixes'!$B$35="","",'Charges fixes'!$B$35) | C37: =IF('Charges fixes'!$B$35="","",IF(OR('Charges fixes'!$D$35="Mensuel",'Charges fixes'!$D$35="",AND('Charges fixes'!$K$35>0,OR(AND('Charges fixes'!$D$35="Trimestriel",MOD(MONTH($B$2)-'Charges fixes'!$K$35+12,3)=0),AND('Charges fixes'!$D$35="Semestriel",MOD(MONTH($B$2)-'Charges fixes'!$K$35+12,6)=0),AND('Charges fixes'!$D$35="Annuel",MONTH($B$2)='Charges fixes'!$K$35)))),N('Charges fixes'!$C$35),0)) | D37: =IF(OR('Charges fixes'!$B$35="",'Charges fixes'!$F$35="",N(C37)=0),"",DATE(YEAR($B$2),MONTH($B$2),MIN('Charges fixes'!$F$35,DAY(EOMONTH($B$2,0))))) | E37: =IF('Charges fixes'!$B$35="","",'Charges fixes'!$G$35&"")
A38: =IF('Charges fixes'!$B$36="","",'Charges fixes'!$A$36&"") | B38: =IF('Charges fixes'!$B$36="","",'Charges fixes'!$B$36) | C38: =IF('Charges fixes'!$B$36="","",IF(OR('Charges fixes'!$D$36="Mensuel",'Charges fixes'!$D$36="",AND('Charges fixes'!$K$36>0,OR(AND('Charges fixes'!$D$36="Trimestriel",MOD(MONTH($B$2)-'Charges fixes'!$K$36+12,3)=0),AND('Charges fixes'!$D$36="Semestriel",MOD(MONTH($B$2)-'Charges fixes'!$K$36+12,6)=0),AND('Charges fixes'!$D$36="Annuel",MONTH($B$2)='Charges fixes'!$K$36)))),N('Charges fixes'!$C$36),0)) | D38: =IF(OR('Charges fixes'!$B$36="",'Charges fixes'!$F$36="",N(C38)=0),"",DATE(YEAR($B$2),MONTH($B$2),MIN('Charges fixes'!$F$36,DAY(EOMONTH($B$2,0))))) | E38: =IF('Charges fixes'!$B$36="","",'Charges fixes'!$G$36&"")
A39: =IF('Charges fixes'!$B$37="","",'Charges fixes'!$A$37&"") | B39: =IF('Charges fixes'!$B$37="","",'Charges fixes'!$B$37) | C39: =IF('Charges fixes'!$B$37="","",IF(OR('Charges fixes'!$D$37="Mensuel",'Charges fixes'!$D$37="",AND('Charges fixes'!$K$37>0,OR(AND('Charges fixes'!$D$37="Trimestriel",MOD(MONTH($B$2)-'Charges fixes'!$K$37+12,3)=0),AND('Charges fixes'!$D$37="Semestriel",MOD(MONTH($B$2)-'Charges fixes'!$K$37+12,6)=0),AND('Charges fixes'!$D$37="Annuel",MONTH($B$2)='Charges fixes'!$K$37)))),N('Charges fixes'!$C$37),0)) | D39: =IF(OR('Charges fixes'!$B$37="",'Charges fixes'!$F$37="",N(C39)=0),"",DATE(YEAR($B$2),MONTH($B$2),MIN('Charges fixes'!$F$37,DAY(EOMONTH($B$2,0))))) | E39: =IF('Charges fixes'!$B$37="","",'Charges fixes'!$G$37&"")
A40: =IF('Charges fixes'!$B$38="","",'Charges fixes'!$A$38&"") | B40: =IF('Charges fixes'!$B$38="","",'Charges fixes'!$B$38) | C40: =IF('Charges fixes'!$B$38="","",IF(OR('Charges fixes'!$D$38="Mensuel",'Charges fixes'!$D$38="",AND('Charges fixes'!$K$38>0,OR(AND('Charges fixes'!$D$38="Trimestriel",MOD(MONTH($B$2)-'Charges fixes'!$K$38+12,3)=0),AND('Charges fixes'!$D$38="Semestriel",MOD(MONTH($B$2)-'Charges fixes'!$K$38+12,6)=0),AND('Charges fixes'!$D$38="Annuel",MONTH($B$2)='Charges fixes'!$K$38)))),N('Charges fixes'!$C$38),0)) | D40: =IF(OR('Charges fixes'!$B$38="",'Charges fixes'!$F$38="",N(C40)=0),"",DATE(YEAR($B$2),MONTH($B$2),MIN('Charges fixes'!$F$38,DAY(EOMONTH($B$2,0))))) | E40: =IF('Charges fixes'!$B$38="","",'Charges fixes'!$G$38&"")
A41: =IF('Charges fixes'!$B$39="","",'Charges fixes'!$A$39&"") | B41: =IF('Charges fixes'!$B$39="","",'Charges fixes'!$B$39) | C41: =IF('Charges fixes'!$B$39="","",IF(OR('Charges fixes'!$D$39="Mensuel",'Charges fixes'!$D$39="",AND('Charges fixes'!$K$39>0,OR(AND('Charges fixes'!$D$39="Trimestriel",MOD(MONTH($B$2)-'Charges fixes'!$K$39+12,3)=0),AND('Charges fixes'!$D$39="Semestriel",MOD(MONTH($B$2)-'Charges fixes'!$K$39+12,6)=0),AND('Charges fixes'!$D$39="Annuel",MONTH($B$2)='Charges fixes'!$K$39)))),N('Charges fixes'!$C$39),0)) | D41: =IF(OR('Charges fixes'!$B$39="",'Charges fixes'!$F$39="",N(C41)=0),"",DATE(YEAR($B$2),MONTH($B$2),MIN('Charges fixes'!$F$39,DAY(EOMONTH($B$2,0))))) | E41: =IF('Charges fixes'!$B$39="","",'Charges fixes'!$G$39&"")
...

Sheet Novembre 2026
A1: Dépenses — Novembre 2026
A2: Mois : | B2: 46327
A3: Total du mois | B3: =SUM(C8:C88) | D3: Rouge = date passée et pas encore payé · Orange = à payer dans les 7 jours
A4: Déjà payé | B4: =SUMIFS(C8:C88,F8:F88,"Oui") | D4: Colonne « Payé ? » : choisissez Oui quand le montant est sorti du compte.
A5: Reste à payer | B5: =B3-B4
A7: Catégorie | B7: Libellé | C7: Montant (€) | D7: Date de paiement / prélèvement | E7: Mode de paiement | F7: Payé ? | G7: Remarques
A8: =IF('Charges fixes'!$B$6="","",'Charges fixes'!$A$6&"") | B8: =IF('Charges fixes'!$B$6="","",'Charges fixes'!$B$6) | C8: =IF('Charges fixes'!$B$6="","",IF(OR('Charges fixes'!$D$6="Mensuel",'Charges fixes'!$D$6="",AND('Charges fixes'!$K$6>0,OR(AND('Charges fixes'!$D$6="Trimestriel",MOD(MONTH($B$2)-'Charges fixes'!$K$6+12,3)=0),AND('Charges fixes'!$D$6="Semestriel",MOD(MONTH($B$2)-'Charges fixes'!$K$6+12,6)=0),AND('Charges fixes'!$D$6="Annuel",MONTH($B$2)='Charges fixes'!$K$6)))),N('Charges fixes'!$C$6),0)) | D8: =IF(OR('Charges fixes'!$B$6="",'Charges fixes'!$F$6="",N(C8)=0),"",DATE(YEAR($B$2),MONTH($B$2),MIN('Charges fixes'!$F$6,DAY(EOMONTH($B$2,0))))) | E8: =IF('Charges fixes'!$B$6="","",'Charges fixes'!$G$6&"")
A9: =IF('Charges fixes'!$B$7="","",'Charges fixes'!$A$7&"") | B9: =IF('Charges fixes'!$B$7="","",'Charges fixes'!$B$7) | C9: =IF('Charges fixes'!$B$7="","",IF(OR('Charges fixes'!$D$7="Mensuel",'Charges fixes'!$D$7="",AND('Charges fixes'!$K$7>0,OR(AND('Charges fixes'!$D$7="Trimestriel",MOD(MONTH($B$2)-'Charges fixes'!$K$7+12,3)=0),AND('Charges fixes'!$D$7="Semestriel",MOD(MONTH($B$2)-'Charges fixes'!$K$7+12,6)=0),AND('Charges fixes'!$D$7="Annuel",MONTH($B$2)='Charges fixes'!$K$7)))),N('Charges fixes'!$C$7),0)) | D9: =IF(OR('Charges fixes'!$B$7="",'Charges fixes'!$F$7="",N(C9)=0),"",DATE(YEAR($B$2),MONTH($B$2),MIN('Charges fixes'!$F$7,DAY(EOMONTH($B$2,0))))) | E9: =IF('Charges fixes'!$B$7="","",'Charges fixes'!$G$7&"")
A10: =IF('Charges fixes'!$B$8="","",'Charges fixes'!$A$8&"") | B10: =IF('Charges fixes'!$B$8="","",'Charges fixes'!$B$8) | C10: =IF('Charges fixes'!$B$8="","",IF(OR('Charges fixes'!$D$8="Mensuel",'Charges fixes'!$D$8="",AND('Charges fixes'!$K$8>0,OR(AND('Charges fixes'!$D$8="Trimestriel",MOD(MONTH($B$2)-'Charges fixes'!$K$8+12,3)=0),AND('Charges fixes'!$D$8="Semestriel",MOD(MONTH($B$2)-'Charges fixes'!$K$8+12,6)=0),AND('Charges fixes'!$D$8="Annuel",MONTH($B$2)='Charges fixes'!$K$8)))),N('Charges fixes'!$C$8),0)) | D10: =IF(OR('Charges fixes'!$B$8="",'Charges fixes'!$F$8="",N(C10)=0),"",DATE(YEAR($B$2),MONTH($B$2),MIN('Charges fixes'!$F$8,DAY(EOMONTH($B$2,0))))) | E10: =IF('Charges fixes'!$B$8="","",'Charges fixes'!$G$8&"")
A11: =IF('Charges fixes'!$B$9="","",'Charges fixes'!$A$9&"") | B11: =IF('Charges fixes'!$B$9="","",'Charges fixes'!$B$9) | C11: =IF('Charges fixes'!$B$9="","",IF(OR('Charges fixes'!$D$9="Mensuel",'Charges fixes'!$D$9="",AND('Charges fixes'!$K$9>0,OR(AND('Charges fixes'!$D$9="Trimestriel",MOD(MONTH($B$2)-'Charges fixes'!$K$9+12,3)=0),AND('Charges fixes'!$D$9="Semestriel",MOD(MONTH($B$2)-'Charges fixes'!$K$9+12,6)=0),AND('Charges fixes'!$D$9="Annuel",MONTH($B$2)='Charges fixes'!$K$9)))),N('Charges fixes'!$C$9),0)) | D11: =IF(OR('Charges fixes'!$B$9="",'Charges fixes'!$F$9="",N(C11)=0),"",DATE(YEAR($B$2),MONTH($B$2),MIN('Charges fixes'!$F$9,DAY(EOMONTH($B$2,0))))) | E11: =IF('Charges fixes'!$B$9="","",'Charges fixes'!$G$9&"")
A12: =IF('Charges fixes'!$B$10="","",'Charges fixes'!$A$10&"") | B12: =IF('Charges fixes'!$B$10="","",'Charges fixes'!$B$10) | C12: =IF('Charges fixes'!$B$10="","",IF(OR('Charges fixes'!$D$10="Mensuel",'Charges fixes'!$D$10="",AND('Charges fixes'!$K$10>0,OR(AND('Charges fixes'!$D$10="Trimestriel",MOD(MONTH($B$2)-'Charges fixes'!$K$10+12,3)=0),AND('Charges fixes'!$D$10="Semestriel",MOD(MONTH($B$2)-'Charges fixes'!$K$10+12,6)=0),AND('Charges fixes'!$D$10="Annuel",MONTH($B$2)='Charges fixes'!$K$10)))),N('Charges fixes'!$C$10),0)) | D12: =IF(OR('Charges fixes'!$B$10="",'Charges fixes'!$F$10="",N(C12)=0),"",DATE(YEAR($B$2),MONTH($B$2),MIN('Charges fixes'!$F$10,DAY(EOMONTH($B$2,0))))) | E12: =IF('Charges fixes'!$B$10="","",'Charges fixes'!$G$10&"")
A13: =IF('Charges fixes'!$B$11="","",'Charges fixes'!$A$11&"") | B13: =IF('Charges fixes'!$B$11="","",'Charges fixes'!$B$11) | C13: =IF('Charges fixes'!$B$11="","",IF(OR('Charges fixes'!$D$11="Mensuel",'Charges fixes'!$D$11="",AND('Charges fixes'!$K$11>0,OR(AND('Charges fixes'!$D$11="Trimestriel",MOD(MONTH($B$2)-'Charges fixes'!$K$11+12,3)=0),AND('Charges fixes'!$D$11="Semestriel",MOD(MONTH($B$2)-'Charges fixes'!$K$11+12,6)=0),AND('Charges fixes'!$D$11="Annuel",MONTH($B$2)='Charges fixes'!$K$11)))),N('Charges fixes'!$C$11),0)) | D13: =IF(OR('Charges fixes'!$B$11="",'Charges fixes'!$F$11="",N(C13)=0),"",DATE(YEAR($B$2),MONTH($B$2),MIN('Charges fixes'!$F$11,DAY(EOMONTH($B$2,0))))) | E13: =IF('Charges fixes'!$B$11="","",'Charges fixes'!$G$11&"")
A14: =IF('Charges fixes'!$B$12="","",'Charges fixes'!$A$12&"") | B14: =IF('Charges fixes'!$B$12="","",'Charges fixes'!$B$12) | C14: =IF('Charges fixes'!$B$12="","",IF(OR('Charges fixes'!$D$12="Mensuel",'Charges fixes'!$D$12="",AND('Charges fixes'!$K$12>0,OR(AND('Charges fixes'!$D$12="Trimestriel",MOD(MONTH($B$2)-'Charges fixes'!$K$12+12,3)=0),AND('Charges fixes'!$D$12="Semestriel",MOD(MONTH($B$2)-'Charges fixes'!$K$12+12,6)=0),AND('Charges fixes'!$D$12="Annuel",MONTH($B$2)='Charges fixes'!$K$12)))),N('Charges fixes'!$C$12),0)) | D14: =IF(OR('Charges fixes'!$B$12="",'Charges fixes'!$F$12="",N(C14)=0),"",DATE(YEAR($B$2),MONTH($B$2),MIN('Charges fixes'!$F$12,DAY(EOMONTH($B$2,0))))) | E14: =IF('Charges fixes'!$B$12="","",'Charges fixes'!$G$12&"")
A15: =IF('Charges fixes'!$B$13="","",'Charges fixes'!$A$13&"") | B15: =IF('Charges fixes'!$B$13="","",'Charges fixes'!$B$13) | C15: =IF('Charges fixes'!$B$13="","",IF(OR('Charges fixes'!$D$13="Mensuel",'Charges fixes'!$D$13="",AND('Charges fixes'!$K$13>0,OR(AND('Charges fixes'!$D$13="Trimestriel",MOD(MONTH($B$2)-'Charges fixes'!$K$13+12,3)=0),AND('Charges fixes'!$D$13="Semestriel",MOD(MONTH($B$2)-'Charges fixes'!$K$13+12,6)=0),AND('Charges fixes'!$D$13="Annuel",MONTH($B$2)='Charges fixes'!$K$13)))),N('Charges fixes'!$C$13),0)) | D15: =IF(OR('Charges fixes'!$B$13="",'Charges fixes'!$F$13="",N(C15)=0),"",DATE(YEAR($B$2),MONTH($B$2),MIN('Charges fixes'!$F$13,DAY(EOMONTH($B$2,0))))) | E15: =IF('Charges fixes'!$B$13="","",'Charges fixes'!$G$13&"")
A16: =IF('Charges fixes'!$B$14="","",'Charges fixes'!$A$14&"") | B16: =IF('Charges fixes'!$B$14="","",'Charges fixes'!$B$14) | C16: =IF('Charges fixes'!$B$14="","",IF(OR('Charges fixes'!$D$14="Mensuel",'Charges fixes'!$D$14="",AND('Charges fixes'!$K$14>0,OR(AND('Charges fixes'!$D$14="Trimestriel",MOD(MONTH($B$2)-'Charges fixes'!$K$14+12,3)=0),AND('Charges fixes'!$D$14="Semestriel",MOD(MONTH($B$2)-'Charges fixes'!$K$14+12,6)=0),AND('Charges fixes'!$D$14="Annuel",MONTH($B$2)='Charges fixes'!$K$14)))),N('Charges fixes'!$C$14),0)) | D16: =IF(OR('Charges fixes'!$B$14="",'Charges fixes'!$F$14="",N(C16)=0),"",DATE(YEAR($B$2),MONTH($B$2),MIN('Charges fixes'!$F$14,DAY(EOMONTH($B$2,0))))) | E16: =IF('Charges fixes'!$B$14="","",'Charges fixes'!$G$14&"")
A17: =IF('Charges fixes'!$B$15="","",'Charges fixes'!$A$15&"") | B17: =IF('Charges fixes'!$B$15="","",'Charges fixes'!$B$15) | C17: =IF('Charges fixes'!$B$15="","",IF(OR('Charges fixes'!$D$15="Mensuel",'Charges fixes'!$D$15="",AND('Charges fixes'!$K$15>0,OR(AND('Charges fixes'!$D$15="Trimestriel",MOD(MONTH($B$2)-'Charges fixes'!$K$15+12,3)=0),AND('Charges fixes'!$D$15="Semestriel",MOD(MONTH($B$2)-'Charges fixes'!$K$15+12,6)=0),AND('Charges fixes'!$D$15="Annuel",MONTH($B$2)='Charges fixes'!$K$15)))),N('Charges fixes'!$C$15),0)) | D17: =IF(OR('Charges fixes'!$B$15="",'Charges fixes'!$F$15="",N(C17)=0),"",DATE(YEAR($B$2),MONTH($B$2),MIN('Charges fixes'!$F$15,DAY(EOMONTH($B$2,0))))) | E17: =IF('Charges fixes'!$B$15="","",'Charges fixes'!$G$15&"")
A18: =IF('Charges fixes'!$B$16="","",'Charges fixes'!$A$16&"") | B18: =IF('Charges fixes'!$B$16="","",'Charges fixes'!$B$16) | C18: =IF('Charges fixes'!$B$16="","",IF(OR('Charges fixes'!$D$16="Mensuel",'Charges fixes'!$D$16="",AND('Charges fixes'!$K$16>0,OR(AND('Charges fixes'!$D$16="Trimestriel",MOD(MONTH($B$2)-'Charges fixes'!$K$16+12,3)=0),AND('Charges fixes'!$D$16="Semestriel",MOD(MONTH($B$2)-'Charges fixes'!$K$16+12,6)=0),AND('Charges fixes'!$D$16="Annuel",MONTH($B$2)='Charges fixes'!$K$16)))),N('Charges fixes'!$C$16),0)) | D18: =IF(OR('Charges fixes'!$B$16="",'Charges fixes'!$F$16="",N(C18)=0),"",DATE(YEAR($B$2),MONTH($B$2),MIN('Charges fixes'!$F$16,DAY(EOMONTH($B$2,0))))) | E18: =IF('Charges fixes'!$B$16="","",'Charges fixes'!$G$16&"")
A19: =IF('Charges fixes'!$B$17="","",'Charges fixes'!$A$17&"") | B19: =IF('Charges fixes'!$B$17="","",'Charges fixes'!$B$17) | C19: =IF('Charges fixes'!$B$17="","",IF(OR('Charges fixes'!$D$17="Mensuel",'Charges fixes'!$D$17="",AND('Charges fixes'!$K$17>0,OR(AND('Charges fixes'!$D$17="Trimestriel",MOD(MONTH($B$2)-'Charges fixes'!$K$17+12,3)=0),AND('Charges fixes'!$D$17="Semestriel",MOD(MONTH($B$2)-'Charges fixes'!$K$17+12,6)=0),AND('Charges fixes'!$D$17="Annuel",MONTH($B$2)='Charges fixes'!$K$17)))),N('Charges fixes'!$C$17),0)) | D19: =IF(OR('Charges fixes'!$B$17="",'Charges fixes'!$F$17="",N(C19)=0),"",DATE(YEAR($B$2),MONTH($B$2),MIN('Charges fixes'!$F$17,DAY(EOMONTH($B$2,0))))) | E19: =IF('Charges fixes'!$B$17="","",'Charges fixes'!$G$17&"")
